<?xml version="1.0"?>

<robot xmlns:xacro="http://www.ros.org/wiki/xacro">

  <xacro:macro name="drive_wheel" params="prefix y_reflect">

    <link name="${prefix}_wheel_link">
      <visual>
        <geometry>
          <cylinder radius="${wheel_radius}" length="${wheel_length}" />
        </geometry>
        <origin xyz="0 0 0" rpy="${PI/2} 0 0" />
        <material name="white" />
      </visual>

      <collision>
        <geometry>
          <cylinder radius="${wheel_radius}" length="${wheel_length}" />
        </geometry>
        <origin xyz="0 0 0" rpy="${PI/2} 0 0" />
      </collision>

      <xacro:cylinder_inertia m="${wheel_mass}" r="${wheel_radius}" h="${wheel_length}" />
    </link>
    <joint name="${prefix}_wheel_joint" type="continuous">
      <parent link="base_link" />
      <child link="${prefix}_wheel_link" />
      <origin 
        xyz="${wheel_offset_x} ${y_reflect * wheel_offset_y} ${wheel_offset_z}" 
        rpy="0 0 0" />
      <axis xyz="0 1 0" />
    </joint>

  </xacro:macro>

  <xacro:drive_wheel prefix="left"  y_reflect="1" />
  <xacro:drive_wheel prefix="right" y_reflect="-1" />

</robot>